Workbook

Sheet Case Study
A5: Case Study: Building a Delivery Performance Dashboard for XYZ Logistics
A7: Background
A8: XYZ Logistics is a mid-sized company specializing in last-mile deliveries in a metropolitan city. They operate in four zones: North, South, East, and West. Due to a recent increase in order volume, fuel costs, and delivery delays, the management wants a dashboard to monitor operational performance and identify areas for improvement.
A10: The dashboard will help:
A12: Monitor delivery performance metrics.
A13: Identify delays and their root causes.
A14: Track cost efficiency.
A15: Visualize trends for actionable insights.
A19: Scenario
A20: You are hired as a logistics analyst at XYZ Logistics. Your manager has tasked you with creating a dashboard using the provided dataset. The dashboard should be visually appealing and provide actionable insights for the operations team.
A22: Here is the sample dataset for one week's deliveries:
A24: | Delivery ID | Zone | Date | Time of Order | Distance (km) | Delivery Time (mins) | Peak Hour (Yes/No) | Delivery Status (On-Time/Delayed) | Fuel Used (liters) | Delivery Cost ($) | Customer Rating (1-5) | |-------------|--------|------------|---------------|---------------|-----------------------|-----------------------------------|--------------------|-------------------|-----------------------| | D001 | North | 2024-11-10 | 8:30 AM | 15 | 120 | Yes | Delayed | 3.0 | 10.0 | 3 | | D002 | South | 2024-11-10 | 9:00 AM | 5 | 45 | Yes | On-Time | 1.5 | 5.0 | 4 | | D003 | East | 2024-11-10 | 3:00 PM | 10 | 60 | No | On-Time | 2.5 | 7.5 | 5 | | D004 | West | 2024-11-10 | 5:15 PM | 20 | 150 | Yes | Delayed | 4.0 | 15.0 | 2 | | D005 | North | 2024-11-11 | 11:00 AM | 7 | 30 | No | On-Time | 1.8 | 6.0 | 4 | | D006 | South | 2024-11-11 | 12:00 PM | 12 | 90 | No | Delayed | 3.2 | 12.0 | 3 | | D007 | East | 2024-11-11 | 6:00 PM | 8 | 45 | Yes | On-Time | 2.0 | 8.0 | 5 | | ... | ... | ... | ... | ... | ... | ... | ... | ... | ... | ... |
... A59: Can you identify trends in fuel usage across zones and peak hours?

Sheet Data
A1: Delivery ID | B1: Zone | C1: Date | D1: Time of Order | E1: Day of Week | F1: Distance (km) | G1: Delivery Time (mins) | H1: Peak Hour (Yes/No) | I1: Delivery Status (On-Time/Delayed) | J1: Fuel Used (liters) | K1: Delivery Cost ($) | L1: Customer Rating (1-5) | M1: Total Deliveries
A2: D001 | B2: West | C2: 2024-11-11 | D2: 06:48 AM | E2: =TEXT(C2, "dddd") -> Monday | F2: 24 | G2: 83 | H2: No | I2: Delayed | J2: 5.07 | K2: 24.9 | L2: 5 | M2: 1
A3: D002 | B3: East | C3: 2024-11-16 | D3: 12:48 PM | E3: =TEXT(C3, "dddd") -> Saturday | F3: 21 | G3: 68 | H3: No | I3: Delayed | J3: 4.32 | K3: 24.86 | L3: 5 | M3: 1
A4: D003 | B4: North | C4: 2024-11-13 | D4: 03:33 PM | E4: =TEXT(C4, "dddd") -> Wednesday | F4: 9 | G4: 77 | H4: No | I4: On-Time | J4: 2.29 | K4: 18.95 | L4: 3 | M4: 1
A5: D004 | B5: North | C5: 2024-11-15 | D5: 10:56 AM | E5: =TEXT(C5, "dddd") -> Friday | F5: 8 | G5: 127 | H5: Yes | I5: On-Time | J5: 1.76 | K5: 17.7 | L5: 1 | M5: 1
A6: D005 | B6: East | C6: 2024-11-10 | D6: 03:40 PM | E6: =TEXT(C6, "dddd") -> Sunday | F6: 16 | G6: 121 | H6: No | I6: On-Time | J6: 3.57 | K6: 14.06 | L6: 4 | M6: 1
A7: D006 | B7: South | C7: 2024-11-13 | D7: 08:33 AM | E7: =TEXT(C7, "dddd") -> Wednesday | F7: 20 | G7: 138 | H7: Yes | I7: Delayed | J7: 4.16 | K7: 21.93 | L7: 4 | M7: 1
A8: D007 | B8: East | C8: 2024-11-11 | D8: 06:14 AM | E8: =TEXT(C8, "dddd") -> Monday | F8: 18 | G8: 42 | H8: No | I8: Delayed | J8: 4.05 | K8: 21.38 | L8: 4 | M8: 1
A9: D008 | B9: East | C9: 2024-11-15 | D9: 12:48 PM | E9: =TEXT(C9, "dddd") -> Friday | F9: 14 | G9: 175 | H9: No | I9: Delayed | J9: 2.99 | K9: 21.17 | L9: 3 | M9: 1
A10: D009 | B10: West | C10: 2024-11-14 | D10: 07:28 PM | E10: =TEXT(C10, "dddd") -> Thursday | F10: 8 | G10: 171 | H10: Yes | I10: On-Time | J10: 1.91 | K10: 11.7 | L10: 4 | M10: 1
A11: D010 | B11: South | C11: 2024-11-11 | D11: 10:10 AM | E11: =TEXT(C11, "dddd") -> Monday | F11: 9 | G11: 117 | H11: Yes | I11: On-Time | J11: 2.04 | K11: 17.69 | L11: 3 | M11: 1
A12: D011 | B12: East | C12: 2024-11-14 | D12: 08:08 AM | E12: =TEXT(C12, "dddd") -> Thursday | F12: 5 | G12: 47 | H12: Yes | I12: Delayed | J12: 1.24 | K12: 10.55 | L12: 5 | M12: 1
A13: D012 | B13: West | C13: 2024-11-15 | D13: 06:10 PM | E13: =TEXT(C13, "dddd") -> Friday | F13: 6 | G13: 144 | H13: Yes | I13: On-Time | J13: 1.49 | K13: 14.34 | L13: 4 | M13: 1
... A101: D100 | B101: West | C101: 2024-11-12 | D101: 10:13 AM | E101: =TEXT(C101, "dddd") -> Tuesday | F101: 8 | G101: 149 | H101: Yes | I101: Delayed | J101: 1.86 | K101: 11.32 | L101: 3 | M101: 1

Sheet Solution
A2: DELIVERY PERFORMANCE
A4: 1️⃣ On-Time Delivery Rate per Zone
A6: Zone's | B6: ON-Time Delivery (In Percentage)
A7: West | B7: =COUNTIFS(Data!B:B,"West",Data!I:I,"On-Time")/COUNTIF(Data!B:B,"West") -> 0.57692308
A8: East | B8: =COUNTIFS(Data!B:B,"East",Data!I:I,"On-Time")/COUNTIF(Data!B:B,"East") -> 0.46666667
A9: North | B9: =COUNTIFS(Data!B:B,"North",Data!I:I,"On-Time")/COUNTIF(Data!B:B,"North") -> 0.36363636
A10: South | B10: =COUNTIFS(Data!B:B,"South",Data!I:I,"On-Time")/COUNTIF(Data!B:B,"South") -> 0.45454545
A12: 2️⃣ Zone with Most Delays
A14: Zone's | B14: Most Delays
A15: West | B15: =COUNTIFS(Data!B:B,"West",Data!I:I,"Delayed") -> 11
A16: East | B16: =COUNTIFS(Data!B:B,"East",Data!I:I,"Delayed") -> 16
A17: North | B17: =COUNTIFS(Data!B:B,"North",Data!I:I,"Delayed") -> 14
A18: South | B18: =COUNTIFS(Data!B:B,"South",Data!I:I,"Delayed") -> 12
A19: Biggest Delay Number | B19: =MAX(B15:B18) -> 16
A20: Maximum Delayed Zone | B20: {=INDEX(A15:A18,MATCH(MAX(B15:B18),B15:B18,))} -> East
A22: OPERATIONAL EFFICIENCY
A24: 3️⃣ Average Delivery Time (mins) Across All Zones
A27: Zone's | B27: Average Delivery Time (mins) Across All Zones
A28: West | B28: =AVERAGEIF(Data!B:B,"West",Data!G:G) -> 108.46154
A29: East | B29: =AVERAGEIF(Data!B:B,"East",Data!G:G) -> 91.7
A30: North | B30: =AVERAGEIF(Data!B:B,"North",Data!G:G) -> 103.81818
A31: South | B31: =AVERAGEIF(Data!B:B,"South",Data!G:G) -> 111.45455
A33: 4️⃣ Peak Hour Impact (on Delivery Time & Cost)
A35: Average Delivery Time (Peak Hours = Yes): | C35: =AVERAGEIF(Data!H:H,"Yes",Data!G:G) -> 104.28205
A37: Average Delivery Time (Peak Hours = No): | C37: =AVERAGEIF(Data!H:H,"No",Data!G:G) -> 102.29508
A39: Average Delivery Cost (Peak Hours = Yes): | C39: =AVERAGEIF(Data!H:H,"Yes",Data!K:K) -> 18.315641
A41: Average Delivery Cost (Peak Hours = No): | C41: =AVERAGEIF(Data!H:H,"No",Data!K:K) -> 17.712131
A44: COST & FUEL ANALYSIS
A46: 5️⃣ Average Fuel Consumption per Zone
A48: Zone's | B48: Fuel Consumption
A49: West | B49: =AVERAGEIF(Data!B:B,"West",Data!J:J) -> 3.4296154
A50: East | B50: =AVERAGEIF(Data!B:B,"East",Data!J:J) -> 3.3723333
A51: North | B51: =AVERAGEIF(Data!B:B,"North",Data!J:J) -> 3.3945455
A52: South | B52: =AVERAGEIF(Data!B:B,"South",Data!J:J) -> 3.6404545
A53: Maximum Fuel Used Number | B53: =MAX(B49:B52) -> 3.6404545
A54: Maximum Fuel Used Zone | B54: {=INDEX(A49:A52,MATCH(MAX(B49:B52),B49:B52,0))} -> South
A56: 6️⃣ Average Delivery Cost per Zone
A58: Zone's | B58: Average Delivery Cost
A59: West | B59: =AVERAGEIF(Data!B:B,"West",Data!K:K) -> 17.719231
A60: East | B60: =AVERAGEIF(Data!B:B,"East",Data!K:K) -> 17.498
...
